Workbook

Sheet insurance
A1: age | B1: sex | C1: bmi | D1: children | E1: smoker | F1: region | G1: charges
A2: 19 | B2: female | C2: 27.9 | D2: 0 | E2: yes | F2: southwest | G2: 16884.924
A3: 18 | B3: male | C3: 33.77 | D3: 1 | E3: no | F3: southeast | G3: 1725.5523
A4: 28 | B4: male | C4: 33 | D4: 3 | E4: no | F4: southeast | G4: 4449.462
A5: 33 | B5: male | C5: 22.705 | D5: 0 | E5: no | F5: northwest | G5: 21984.471
A6: 32 | B6: male | C6: 28.88 | D6: 0 | E6: no | F6: northwest | G6: 3866.8552
A7: 31 | B7: female | C7: 25.74 | D7: 0 | E7: no | F7: southeast | G7: 3756.6216
A8: 46 | B8: female | C8: 33.44 | D8: 1 | E8: no | F8: southeast | G8: 8240.5896
A9: 37 | B9: female | C9: 27.74 | D9: 3 | E9: no | F9: northwest | G9: 7281.5056
A10: 37 | B10: male | C10: 29.83 | D10: 2 | E10: no | F10: northeast | G10: 6406.4107
A11: 60 | B11: female | C11: 25.84 | D11: 0 | E11: no | F11: northwest | G11: 28923.137
A12: 25 | B12: male | C12: 26.22 | D12: 0 | E12: no | F12: northeast | G12: 2721.3208
A13: 62 | B13: female | C13: 26.29 | D13: 0 | E13: yes | F13: southeast | G13: 27808.725
... A1339: 61 | B1339: female | C1339: 29.07 | D1339: 0 | E1339: yes | F1339: northwest | G1339: 29141.36

Sheet Processed Data
A1: Age | B1: Sex | C1: BMI | D1: Children | E1: Smoker | F1: Region | G1: Charges
A2: 19 | B2: 0 | C2: 27.9 | D2: 0 | E2: 1 | F2: 2 | G2: 16884.924
A3: 18 | B3: 1 | C3: 33.77 | D3: 1 | E3: 0 | F3: 1 | G3: 1725.5523
A4: 28 | B4: 1 | C4: 33 | D4: 3 | E4: 0 | F4: 1 | G4: 4449.462
A5: 33 | B5: 1 | C5: 22.705 | D5: 0 | E5: 0 | F5: 3 | G5: 21984.471
A6: 32 | B6: 1 | C6: 28.88 | D6: 0 | E6: 0 | F6: 3 | G6: 3866.8552
A7: 31 | B7: 0 | C7: 25.74 | D7: 0 | E7: 0 | F7: 1 | G7: 3756.6216
A8: 46 | B8: 0 | C8: 33.44 | D8: 1 | E8: 0 | F8: 1 | G8: 8240.5896
A9: 37 | B9: 0 | C9: 27.74 | D9: 3 | E9: 0 | F9: 3 | G9: 7281.5056
A10: 37 | B10: 1 | C10: 29.83 | D10: 2 | E10: 0 | F10: 0 | G10: 6406.4107
A11: 60 | B11: 0 | C11: 25.84 | D11: 0 | E11: 0 | F11: 3 | G11: 28923.137
A12: 25 | B12: 1 | C12: 26.22 | D12: 0 | E12: 0 | F12: 0 | G12: 2721.3208
A13: 62 | B13: 0 | C13: 26.29 | D13: 0 | E13: 1 | F13: 1 | G13: 27808.725
... A1339: 61 | B1339: 0 | C1339: 29.07 | D1339: 0 | E1339: 1 | F1339: 3 | G1339: 29141.36

Sheet Descriptive Statistics
A1: Parameter | B1: Age | C1: Sex | D1: BMI | E1: Children | F1: Smoker | G1: Region | H1: Charges
A2: Mean | B2: 39.207025 | C2: 0.50523169 | D2: 30.663397 | E2: 1.0949178 | F2: 0.20478326 | G2: 1.4865471 | H2: 13270.422
A3: Standard Error | B3: 0.38410242 | C3: 0.013673526 | D3: 0.16671423 | E3: 0.032956155 | F3: 0.01103632 | G3: 0.030206515 | H3: 331.06745
A4: Median | B4: 39 | C4: 1 | D4: 30.4 | E4: 1 | F4: 0 | G4: 1 | H4: 9382.033
A5: Mode | B5: 18 | C5: 1 | D5: 32.3 | E5: 0 | F5: 0 | G5: 1 | H5: 1639.5631
A6: Standard Deviation | B6: 14.04996 | C6: 0.50015957 | D6: 6.0981869 | E6: 1.2054927 | F6: 0.40369404 | G6: 1.1049145 | H6: 12110.011
A7: Sample Variance | B7: 197.40139 | C7: 0.25015959 | D7: 37.187884 | E7: 1.4532127 | F7: 0.16296888 | G7: 1.2208361 | H7: 1.4665237e+08
A8: Kurtosis | B8: -1.2450877 | C8: -2.0025566 | D8: -0.050731531 | E8: 0.20245415 | F8: 0.14575554 | G8: -1.3279841 | H8: 1.6062987
A9: Skewness | B9: 0.055672516 | C9: -0.020951397 | D9: 0.28404711 | E9: 0.93838044 | F9: 1.4647662 | G9: 0.035750107 | H9: 1.5158797
A10: Range | B10: 46 | C10: 1 | D10: 37.17 | E10: 5 | F10: 1 | G10: 3 | H10: 62648.554
A11: Minimum | B11: 18 | C11: 0 | D11: 15.96 | E11: 0 | F11: 0 | G11: 0 | H11: 1121.8739
A12: Maximum | B12: 64 | C12: 1 | D12: 53.13 | E12: 5 | F12: 1 | G12: 3 | H12: 63770.428
A13: Sum | B13: 52459 | C13: 676 | D13: 41027.625 | E13: 1465 | F13: 274 | G13: 1989 | H13: 17755825
... A15: Confidence Level(95.0%) | B15: 0.75350904 | C15: 0.026823902 | D15: 0.32704996 | E15: 0.064651405 | F15: 0.021650389 | G15: 0.059257325 | H15: 649.46823

Sheet Histograms

Sheet Scatter Plots

Sheet Correlation
B1: Age | C1: Sex | D1: BMI | E1: Children | F1: Smoker | G1: Region | H1: Charges
A2: Age | B2: =CORREL('Processed Data'!A:A,'Processed Data'!A:A) -> 1 | C2: =CORREL('Processed Data'!B:B,'Processed Data'!A:A) -> -0.020855872 | D2: =CORREL('Processed Data'!C:C,'Processed Data'!A:A) -> 0.10927188 | E2: =CORREL('Processed Data'!D:D,'Processed Data'!A:A) -> 0.042468999 | F2: =CORREL('Processed Data'!E:E,'Processed Data'!A:A) -> -0.025018752 | G2: =CORREL('Processed Data'!F:F,'Processed Data'!A:A) -> 0.0026126188 | H2: =CORREL('Processed Data'!G:G,'Processed Data'!A:A) -> 0.29900819
A3: Sex | B3: =CORREL('Processed Data'!A:A,'Processed Data'!B:B) -> -0.020855872 | C3: =CORREL('Processed Data'!B:B,'Processed Data'!B:B) -> 1 | D3: =CORREL('Processed Data'!C:C,'Processed Data'!B:B) -> 0.046371151 | E3: =CORREL('Processed Data'!D:D,'Processed Data'!B:B) -> 0.017162978 | F3: =CORREL('Processed Data'!E:E,'Processed Data'!B:B) -> 0.076184817 | G3: =CORREL('Processed Data'!F:F,'Processed Data'!B:B) -> -0.0093464608 | H3: =CORREL('Processed Data'!G:G,'Processed Data'!B:B) -> 0.057292062
A4: BMI | B4: =CORREL('Processed Data'!A:A,'Processed Data'!C:C) -> 0.10927188 | C4: =CORREL('Processed Data'!B:B,'Processed Data'!C:C) -> 0.046371151 | D4: =CORREL('Processed Data'!C:C,'Processed Data'!C:C) -> 1 | E4: =CORREL('Processed Data'!D:D,'Processed Data'!C:C) -> 0.012758901 | F4: =CORREL('Processed Data'!E:E,'Processed Data'!C:C) -> 0.0037504259 | G4: =CORREL('Processed Data'!F:F,'Processed Data'!C:C) -> -0.054428256 | H4: =CORREL('Processed Data'!G:G,'Processed Data'!C:C) -> 0.19834097
A5: Children | B5: =CORREL('Processed Data'!A:A,'Processed Data'!D:D) -> 0.042468999 | C5: =CORREL('Processed Data'!B:B,'Processed Data'!D:D) -> 0.017162978 | D5: =CORREL('Processed Data'!C:C,'Processed Data'!D:D) -> 0.012758901 | E5: =CORREL('Processed Data'!D:D,'Processed Data'!D:D) -> 1 | F5: =CORREL('Processed Data'!E:E,'Processed Data'!D:D) -> 0.0076731203 | G5: =CORREL('Processed Data'!F:F,'Processed Data'!D:D) -> 0.036616739 | H5: =CORREL('Processed Data'!G:G,'Processed Data'!D:D) -> 0.067998227
A6: Smoker | B6: =CORREL('Processed Data'!A:A,'Processed Data'!E:E) -> -0.025018752 | C6: =CORREL('Processed Data'!B:B,'Processed Data'!E:E) -> 0.076184817 | D6: =CORREL('Processed Data'!C:C,'Processed Data'!E:E) -> 0.0037504259 | E6: =CORREL('Processed Data'!D:D,'Processed Data'!E:E) -> 0.0076731203 | F6: =CORREL('Processed Data'!E:E,'Processed Data'!E:E) -> 1 | G6: =CORREL('Processed Data'!F:F,'Processed Data'!E:E) -> -0.044123791 | H6: =CORREL('Processed Data'!G:G,'Processed Data'!E:E) -> 0.78725143
A7: Region | B7: =CORREL('Processed Data'!A:A,'Processed Data'!F:F) -> 0.0026126188 | C7: =CORREL('Processed Data'!B:B,'Processed Data'!F:F) -> -0.0093464608 | D7: =CORREL('Processed Data'!C:C,'Processed Data'!F:F) -> -0.054428256 | E7: =CORREL('Processed Data'!D:D,'Processed Data'!F:F) -> 0.036616739 | F7: =CORREL('Processed Data'!E:E,'Processed Data'!F:F) -> -0.044123791 | G7: =CORREL('Processed Data'!F:F,'Processed Data'!F:F) -> 1 | H7: =CORREL('Processed Data'!G:G,'Processed Data'!F:F) -> -0.050226196
A8: Charges | B8: =CORREL('Processed Data'!A:A,'Processed Data'!G:G) -> 0.29900819 | C8: =CORREL('Processed Data'!B:B,'Processed Data'!G:G) -> 0.057292062 | D8: =CORREL('Processed Data'!C:C,'Processed Data'!G:G) -> 0.19834097 | E8: =CORREL('Processed Data'!D:D,'Processed Data'!G:G) -> 0.067998227 | F8: =CORREL('Processed Data'!E:E,'Processed Data'!G:G) -> 0.78725143 | G8: =CORREL('Processed Data'!F:F,'Processed Data'!G:G) -> -0.050226196 | H8: =CORREL('Processed Data'!G:G,'Processed Data'!G:G) -> 1

Sheet T Test Medical Charges
A1: Sex | B1: Charges | D1: Male Charges | E1: Female Charges | H1: t-Test: Two-Sample Assuming Equal Variances
A2: 0 | B2: 16884.924 | D2: 1725.5523 | E2: 16884.924
A3: 1 | B3: 1725.5523 | D3: 4449.462 | E3: 3756.6216 | I3: Male Charges | J3: Female Charges
A4: 1 | B4: 4449.462 | D4: 21984.471 | E4: 8240.5896 | H4: Mean | I4: 13956.751 | J4: 12569.579
A5: 1 | B5: 21984.471 | D5: 3866.8552 | E5: 7281.5056 | H5: Variance | I5: 1.6824751e+08 | J5: 1.2384805e+08
A6: 1 | B6: 3866.8552 | D6: 6406.4107 | E6: 28923.137 | H6: Observations | I6: 676 | J6: 662
A7: 0 | B7: 3756.6216 | D7: 2721.3208 | E7: 27808.725 | H7: Pooled Variance | I7: 1.4628041e+08
A8: 0 | B8: 8240.5896 | D8: 1826.843 | E8: 11090.718 | H8: Hypothesized Mean Difference | I8: 0
A9: 0 | B9: 7281.5056 | D9: 39611.758 | E9: 10797.336 | H9: df | I9: 1336
A10: 1 | B10: 6406.4107 | D10: 1837.237 | E10: 13228.847 | H10: t Stat | I10: 2.0975466
A11: 0 | B11: 28923.137 | D11: 2395.1716 | E11: 4149.736 | H11: P(T<=t) one-tail | I11: 0.018066361
A12: 1 | B12: 2721.3208 | D12: 10602.385 | E12: 37701.877 | H12: t Critical one-tail | I12: 1.645995
A13: 0 | B13: 27808.725 | D13: 36837.467 | E13: 14001.134 | H13: P(T<=t) two-tail | I13: 0.036132721
A14: 1 | B14: 1826.843 | D14: 1137.011 | E14: 14451.835 | H14: t Critical two-tail | I14: 1.9617412
A15: 0 | B15: 11090.718 | D15: 6203.9017 | E15: 12268.632
A16: 1 | B16: 39611.758 | D16: 2775.1921 | E16: 2198.1899
A17: 1 | B17: 1837.237 | D17: 38711 | E17: 4687.797
A18: 0 | B18: 10797.336 | D18: 35585.576 | E18: 15612.193
A19: 1 | B19: 2395.1716 | D19: 13770.098 | E19: 3046.062
A20: 1 | B20: 10602.385 | D20: 51194.559 | E20: 4949.7587
A21: 1 | B21: 36837.467 | D21: 1625.4337 | E21: 6313.759
A22: 0 | B22: 13228.847 | D22: 2302.3 | E22: 3393.3564
A23: 0 | B23: 4149.736 | D23: 39774.276 | E23: 3556.9223
A24: 1 | B24: 1137.011 | D24: 48173.361 | E24: 12629.897
A25: 0 | B25: 37701.877 | D25: 6272.4772 | E25: 2211.1307
A26: 1 | B26: 6203.9017 | D26: 6079.6715 | E26: 3579.8287
... A663: 0 | B663: 22192.437 | D663: 21472.479 | E663: 29141.36
A664: 0 | B664: 5148.5526 | D664: 6875.961
A665: 1 | B665: 1136.3994 | D665: 6940.9099
A666: 0 | B666: 27037.914 | D666: 4536.259
A667: 1 | B667: 42560.43 | D667: 11272.331
A668: 1 | B668: 8703.456 | D668: 1163.4627
A669: 0 | B669: 40003.332 | D669: 19496.719
A670: 1 | B670: 45710.208 | D670: 5425.0234
A671: 0 | B671: 6500.2359 | D671: 28101.333
A672: 1 | B672: 4837.5823 | D672: 12981.346
A673: 0 | B673: 3943.5954 | D673: 4239.8926
A674: 1 | B674: 4399.731 | D674: 13143.337
A675: 0 | B675: 6185.3208 | D675: 9377.9047
... A677: 1 | B677: 7222.7863 | D677: 10600.548
...

Sheet T Test Smoking Medical Charges
A1: Smoker | B1: Charges | D1: Non Smokers | E1: Smokers | H1: t-Test: Two-Sample Assuming Equal Variances
A2: 1 | B2: 16884.924 | D2: 1725.5523 | E2: 16884.924
A3: 0 | B3: 1725.5523 | D3: 4449.462 | E3: 27808.725 | I3: Non Smokers | J3: Smokers
A4: 0 | B4: 4449.462 | D4: 21984.471 | E4: 39611.758 | H4: Mean | I4: 8434.2683 | J4: 32050.232
A5: 0 | B5: 21984.471 | D5: 3866.8552 | E5: 36837.467 | H5: Variance | I5: 35925420 | J5: 1.3320731e+08
A6: 0 | B6: 3866.8552 | D6: 3756.6216 | E6: 37701.877 | H6: Observations | I6: 1064 | J6: 274
A7: 0 | B7: 3756.6216 | D7: 8240.5896 | E7: 38711 | H7: Pooled Variance | I7: 55804130
A8: 0 | B8: 8240.5896 | D8: 7281.5056 | E8: 35585.576 | H8: Hypothesized Mean Difference | I8: 0
A9: 0 | B9: 7281.5056 | D9: 6406.4107 | E9: 51194.559 | H9: df | I9: 1336
A10: 0 | B10: 6406.4107 | D10: 28923.137 | E10: 39774.276 | H10: t Stat | I10: -46.664921
A11: 0 | B11: 28923.137 | D11: 2721.3208 | E11: 48173.361 | H11: P(T<=t) one-tail | I11: 4.1357179e-283
A12: 0 | B12: 2721.3208 | D12: 1826.843 | E12: 38709.176 | H12: t Critical one-tail | I12: 1.645995
A13: 1 | B13: 27808.725 | D13: 11090.718 | E13: 23568.272 | H13: P(T<=t) two-tail | I13: 8.2714358e-283
A14: 0 | B14: 1826.843 | D14: 1837.237 | E14: 37742.576 | H14: t Critical two-tail | I14: 1.9617412
A15: 0 | B15: 11090.718 | D15: 10797.336 | E15: 47496.494
A16: 1 | B16: 39611.758 | D16: 2395.1716 | E16: 34303.167
A17: 0 | B17: 1837.237 | D17: 10602.385 | E17: 23244.79
A18: 0 | B18: 10797.336 | D18: 13228.847 | E18: 14711.744
A19: 0 | B19: 2395.1716 | D19: 4149.736 | E19: 17663.144
A20: 0 | B20: 10602.385 | D20: 1137.011 | E20: 16577.78
A21: 1 | B21: 36837.467 | D21: 6203.9017 | E21: 37165.164
A22: 0 | B22: 13228.847 | D22: 14001.134 | E22: 39836.519
A23: 0 | B23: 4149.736 | D23: 14451.835 | E23: 21098.554
A24: 0 | B24: 1137.011 | D24: 12268.632 | E24: 43578.939
A25: 1 | B25: 37701.877 | D25: 2775.1921 | E25: 30184.937
A26: 0 | B26: 6203.9017 | D26: 2198.1899 | E26: 47291.055
... A275: 0 | B275: 9617.6624 | D275: 14133.038 | E275: 29141.36
A276: 0 | B276: 2523.1695 | D276: 24603.048
A277: 0 | B277: 9715.841 | D277: 8944.1151
A278: 0 | B278: 2803.6979 | D278: 9620.3307
A279: 0 | B279: 2150.469 | D279: 1837.2819
A280: 0 | B280: 12928.791 | D280: 1607.5101
A281: 0 | B281: 9855.1314 | D281: 10043.249
A282: 1 | B282: 22331.567 | D282: 4751.07
A283: 1 | B283: 48549.178 | D283: 2597.779
A284: 0 | B284: 4237.1265 | D284: 3180.5101
A285: 0 | B285: 11879.104 | D285: 9778.3472
A286: 0 | B286: 9625.92 | D286: 13430.265
A287: 0 | B287: 7742.1098 | D287: 8017.0612
... A1065: 0 | B1065: 6548.1951 | D1065: 2007.945
...

Sheet Regression Output
A1: SUMMARY OUTPUT
A3: Regression Statistics
A4: Multiple R | B4: 0.87125625
A5: R Square | B5: 0.75908745
A6: Adjusted R Square | B6: 0.75753317
A7: Standard Error | B7: 5930.9912
A8: Observations | B8: 937
A10: ANOVA
B11: df | C11: SS | D11: MS | E11: F | F11: Significance F
A12: Regression | B12: 6 | C12: 1.0307893e+11 | D12: 1.7179821e+10 | E12: 488.38698 | F12: 2.3039991e-283
A13: Residual | B13: 930 | C13: 3.2714291e+10 | D13: 35176657
A14: Total | B14: 936 | C14: 1.3579322e+11
B16: Coefficients | C16: Standard Error | D16: t Stat | E16: P-value | F16: Lower 95% | G16: Upper 95% | H16: Lower 95.0% | I16: Upper 95.0%
A17: Intercept | B17: -11913.967 | C17: 1178.6261 | D17: -10.108351 | E17: 7.3142495e-23 | F17: -14227.042 | G17: -9600.8917 | H17: -14227.042 | I17: -9600.8917
A18: Age | B18: 260.71497 | C18: 13.701477 | D18: 19.028238 | E18: 1.9435673e-68 | F18: 233.82557 | G18: 287.60437 | H18: 233.82557 | I18: 287.60437
A19: Sex | B19: -367.29549 | C19: 389.36382 | D19: -0.94332209 | E19: 0.34576117 | F19: -1131.429 | G19: 396.83804 | H19: -1131.429 | I19: 396.83804
A20: BMI | B20: 320.67638 | C20: 32.488822 | D20: 9.8703605 | E20: 6.393494e-22 | F20: 256.91648 | G20: 384.43628 | H20: 256.91648 | I20: 384.43628
A21: Children | B21: 439.10541 | C21: 163.40406 | D21: 2.6872369 | E21: 0.0073331951 | F21: 118.42199 | G21: 759.78882 | H21: 118.42199 | I21: 759.78882
A22: Smoker | B22: 24022.904 | C22: 489.71063 | D22: 49.055304 | E22: 3.2153161e-260 | F22: 23061.838 | G22: 24983.969 | H22: 23061.838 | I22: 24983.969
A23: Region | B23: -154.5725 | C23: 177.83528 | D23: -0.86918922 | E23: 0.3849679 | F23: -503.57745 | G23: 194.43244 | H23: -503.57745 | I23: 194.43244
A27: RESIDUAL OUTPUT
A29: Observation | B29: Predicted Charges | C29: Residuals
A30: 1 | B30: 25700.247 | C30: -8815.3231
A31: 2 | B31: 3525.3814 | C31: -1799.8291
A32: 3 | B32: 6763.8211 | C32: -2314.3591
A33: 4 | B33: 3139.5714 | C33: 18844.899
A34: 5 | B34: 4859.0331 | C34: -992.1779
A35: 6 | B35: 4267.8348 | C35: -511.21319
A36: 7 | B36: 11086.873 | C36: -2846.2833
A37: 8 | B37: 7481.6486 | C37: -200.14298
A38: 9 | B38: 7809.1788 | C38: -1402.7681
A39: 10 | B39: 11551.492 | C39: 17371.645
A40: 11 | B40: 2644.7467 | C40: 76.574143
A41: 12 | B41: 36549.274 | C41: -8740.5493
... A966: 937 | B966: 9603.7194 | C966: 22504.943

Sheet Training Data Actual Vs Predict
A1: Charges | B1: Predicted Charges | C1: Error | D1: Squared Error | E1: Absolute Error | F1: Aboslute % Error
A2: 16884.924 | B2: 25700.247 | C2: =A2-B2 -> -8815.3231 | D2: =C2^2 -> 77709922 | E2: =ABS(C2) -> 8815.3231 | F2: =E2/A2*100 -> 52.208249 | H2: MSE | I2: {=SUM(D:D)/COUNT(D:D-1)} -> 31198.809
A3: 1725.5523 | B3: 3525.3814 | C3: =A3-B3 -> -1799.8291 | D3: =C3^2 -> 3239384.9 | E3: =ABS(C3) -> 1799.8291 | F3: =E3/A3*100 -> 104.30453 | H3: MAD | I3: {=SUM(E:E)/COUNT(D:D-1)} -> 3.5855028
A4: 4449.462 | B4: 6763.8211 | C4: =A4-B4 -> -2314.3591 | D4: =C4^2 -> 5356258.2 | E4: =ABS(C4) -> 2314.3591 | F4: =E4/A4*100 -> 52.014359 | H4: MAPE | I4: {=SUM(F:F)/COUNT(D:D-1)} -> 0.036456853
A5: 21984.471 | B5: 3139.5714 | C5: =A5-B5 -> 18844.899 | D5: =C5^2 -> 3.5513023e+08 | E5: =ABS(C5) -> 18844.899 | F5: =E5/A5*100 -> 85.71914
A6: 3866.8552 | B6: 4859.0331 | C6: =A6-B6 -> -992.1779 | D6: =C6^2 -> 984416.98 | E6: =ABS(C6) -> 992.1779 | F6: =E6/A6*100 -> 25.658522
A7: 3756.6216 | B7: 4267.8348 | C7: =A7-B7 -> -511.21319 | D7: =C7^2 -> 261338.93 | E7: =ABS(C7) -> 511.21319 | F7: =E7/A7*100 -> 13.608323
A8: 8240.5896 | B8: 11086.873 | C8: =A8-B8 -> -2846.2833 | D8: =C8^2 -> 8101328.4 | E8: =ABS(C8) -> 2846.2833 | F8: =E8/A8*100 -> 34.539801
A9: 7281.5056 | B9: 7481.6486 | C9: =A9-B9 -> -200.14298 | D9: =C9^2 -> 40057.213 | E9: =ABS(C9) -> 200.14298 | F9: =E9/A9*100 -> 2.7486483
A10: 6406.4107 | B10: 7809.1788 | C10: =A10-B10 -> -1402.7681 | D10: =C10^2 -> 1967758.4 | E10: =ABS(C10) -> 1402.7681 | F10: =E10/A10*100 -> 21.896319
A11: 28923.137 | B11: 11551.492 | C11: =A11-B11 -> 17371.645 | D11: =C11^2 -> 3.0177406e+08 | E11: =ABS(C11) -> 17371.645 | F11: =E11/A11*100 -> 60.061415
A12: 2721.3208 | B12: 2644.7467 | C12: =A12-B12 -> 76.574143 | D12: =C12^2 -> 5863.5994 | E12: =ABS(C12) -> 76.574143 | F12: =E12/A12*100 -> 2.8138595
A13: 27808.725 | B13: 36549.274 | C13: =A13-B13 -> -8740.5493 | D13: =C13^2 -> 76397201 | E13: =ABS(C13) -> 8740.5493 | F13: =E13/A13*100 -> 31.43096
A14: 1826.843 | B14: 4437.3045 | C14: =A14-B14 -> -2610.4615 | D14: =C14^2 -> 6814509.2 | E14: =ABS(C14) -> 2610.4615 | F14: =E14/A14*100 -> 142.89468
A15: 11090.718 | B15: 15300.832 | C15: =A15-B15 -> -4210.1146 | D15: =C15^2 -> 17725065 | E15: =ABS(C15) -> 4210.1146 | F15: =E15/A15*100 -> 37.960705
A16: 39611.758 | B16: 32136.469 | C16: =A16-B16 -> 7475.2889 | D16: =C16^2 -> 55879944 | E16: =ABS(C16) -> 7475.2889 | F16: =E16/A16*100 -> 18.871389
... A938: 32108.663 | B938: 9603.7194 | C938: =A938-B938 -> 22504.943 | D938: =C938^2 -> 5.0647248e+08 | E938: =ABS(C938) -> 22504.943 | F938: =E938/A938*100 -> 70.089943

Sheet Validation
A1: Age | B1: Sex | C1: BMI | D1: Children | E1: Smoker | F1: Region | G1: Charges | H1: Predicted Charges | I1: Error | J1: Squared Error | K1: Absolute Error | L1: Aboslute % Error
A2: 39 | B2: 0 | C2: 24.225 | D2: 5 | E2: 0 | F2: 3 | G2: 8965.7957 | H2: =(A2*$O$9)+(B2*$O$10)+(C2*$O$11)+(D2*$O$12)+(E2*$O$13)+(F2*$O$14)+$O$8 -> 7754.1119 | I2: =G2-H2 -> 1211.6839 | J2: =I2^2 -> 1468177.8 | K2: =ABS(I2) -> 1211.6839 | L2: =K2/G2*100 -> 13.514516 | N2: MSE | O2: {=SUM(J:J)/COUNT(J:J-1)} -> 15648.48
A3: 18 | B3: 1 | C3: 26.18 | D3: 2 | E3: 0 | F3: 1 | G3: 2304.0022 | H3: =(A3*$O$9)+(B3*$O$10)+(C3*$O$11)+(D3*$O$12)+(E3*$O$13)+(F3*$O$14)+$O$8 -> 1530.5531 | I3: =G3-H3 -> 773.44907 | J3: =I3^2 -> 598223.46 | K3: =ABS(I3) -> 773.44907 | L3: =K3/G3*100 -> 33.569806 | N3: MAD | O3: {=SUM(K:K)/COUNT(J:J-1)} -> 1.6808271
A4: 53 | B4: 1 | C4: 29.48 | D4: 0 | E4: 0 | F4: 1 | G4: 9487.6442 | H4: =(A4*$O$9)+(B4*$O$10)+(C4*$O$11)+(D4*$O$12)+(E4*$O$13)+(F4*$O$14)+$O$8 -> 10835.598 | I4: =G4-H4 -> -1347.9541 | J4: =I4^2 -> 1816980.2 | K4: =ABS(I4) -> 1347.9541 | L4: =K4/G4*100 -> 14.207469 | N4: MAPE | O4: {=SUM(L:L)/COUNT(J:J-1)} -> 0.015904158
A5: 18 | B5: 1 | C5: 23.21 | D5: 0 | E5: 0 | F5: 1 | G5: 1121.8739 | H5: =(A5*$O$9)+(B5*$O$10)+(C5*$O$11)+(D5*$O$12)+(E5*$O$13)+(F5*$O$14)+$O$8 -> -300.06653 | I5: =G5-H5 -> 1421.9404 | J5: =I5^2 -> 2021914.6 | K5: =ABS(I5) -> 1421.9404 | L5: =K5/G5*100 -> 126.7469
A6: 50 | B6: 0 | C6: 46.09 | D6: 1 | E6: 0 | F6: 1 | G6: 9549.5651 | H6: =(A6*$O$9)+(B6*$O$10)+(C6*$O$11)+(D6*$O$12)+(E6*$O$13)+(F6*$O$14)+$O$8 -> 16186.289 | I6: =G6-H6 -> -6636.7238 | J6: =I6^2 -> 44046103 | K6: =ABS(I6) -> 6636.7238 | L6: =K6/G6*100 -> 69.497655
A7: 18 | B7: 0 | C7: 40.185 | D7: 0 | E7: 0 | F7: 0 | G7: 2217.4691 | H7: =(A7*$O$9)+(B7*$O$10)+(C7*$O$11)+(D7*$O$12)+(E7*$O$13)+(F7*$O$14)+$O$8 -> 5665.283 | I7: =G7-H7 -> -3447.8139 | J7: =I7^2 -> 11887420 | K7: =ABS(I7) -> 3447.8139 | L7: =K7/G7*100 -> 155.48419
A8: 19 | B8: 1 | C8: 22.61 | D8: 0 | E8: 0 | F8: 3 | G8: 1628.4709 | H8: =(A8*$O$9)+(B8*$O$10)+(C8*$O$11)+(D8*$O$12)+(E8*$O$13)+(F8*$O$14)+$O$8 -> -540.9024 | I8: =G8-H8 -> 2169.3733 | J8: =I8^2 -> 4706180.5 | K8: =ABS(I8) -> 2169.3733 | L8: =K8/G8*100 -> 133.21536 | N8: Intercept | O8: -11913.967
A9: 62 | B9: 1 | C9: 39.93 | D9: 0 | E9: 0 | F9: 1 | G9: 12982.875 | H9: =(A9*$O$9)+(B9*$O$10)+(C9*$O$11)+(D9*$O$12)+(E9*$O$13)+(F9*$O$14)+$O$8 -> 16533.101 | I9: =G9-H9 -> -3550.2265 | J9: =I9^2 -> 12604108 | K9: =ABS(I9) -> 3550.2265 | L9: =K9/G9*100 -> 27.345457 | N9: Age | O9: 260.71497
A10: 56 | B10: 0 | C10: 35.8 | D10: 1 | E10: 0 | F10: 2 | G10: 11674.13 | H10: =(A10*$O$9)+(B10*$O$10)+(C10*$O$11)+(D10*$O$12)+(E10*$O$13)+(F10*$O$14)+$O$8 -> 14296.246 | I10: =G10-H10 -> -2622.1163 | J10: =I10^2 -> 6875493.9 | K10: =ABS(I10) -> 2622.1163 | L10: =K10/G10*100 -> 22.460914 | N10: Sex | O10: -367.29549
A11: 42 | B11: 1 | C11: 35.8 | D11: 2 | E11: 0 | F11: 2 | G11: 7160.094 | H11: =(A11*$O$9)+(B11*$O$10)+(C11*$O$11)+(D11*$O$12)+(E11*$O$13)+(F11*$O$14)+$O$8 -> 10718.047 | I11: =G11-H11 -> -3557.9527 | J11: =I11^2 -> 12659027 | K11: =ABS(I11) -> 3557.9527 | L11: =K11/G11*100 -> 49.691424 | N11: BMI | O11: 320.67638
A12: 37 | B12: 1 | C12: 34.2 | D12: 1 | E12: 1 | F12: 0 | G12: 39047.285 | H12: =(A12*$O$9)+(B12*$O$10)+(C12*$O$11)+(D12*$O$12)+(E12*$O$13)+(F12*$O$14)+$O$8 -> 32794.333 | I12: =G12-H12 -> 6252.9523 | J12: =I12^2 -> 39099412 | K12: =ABS(I12) -> 6252.9523 | L12: =K12/G12*100 -> 16.013795 | N12: Children | O12: 439.10541
A13: 42 | B13: 1 | C13: 31.255 | D13: 0 | E13: 0 | F13: 3 | G13: 6358.7765 | H13: =(A13*$O$9)+(B13*$O$10)+(C13*$O$11)+(D13*$O$12)+(E13*$O$13)+(F13*$O$14)+$O$8 -> 8227.7892 | I13: =G13-H13 -> -1869.0127 | J13: =I13^2 -> 3493208.6 | K13: =ABS(I13) -> 1869.0127 | L13: =K13/G13*100 -> 29.392647 | N13: Smoker | O13: 24022.904
A14: 25 | B14: 1 | C14: 29.7 | D14: 3 | E14: 1 | F14: 2 | G14: 19933.458 | H14: =(A14*$O$9)+(B14*$O$10)+(C14*$O$11)+(D14*$O$12)+(E14*$O$13)+(F14*$O$14)+$O$8 -> 28791.775 | I14: =G14-H14 -> -8858.3172 | J14: =I14^2 -> 78469783 | K14: =ABS(I14) -> 8858.3172 | L14: =K14/G14*100 -> 44.43944 | N14: Region | O14: -154.5725
A15: 57 | B15: 1 | C15: 18.335 | D15: 0 | E15: 0 | F15: 0 | G15: 11534.873 | H15: =(A15*$O$9)+(B15*$O$10)+(C15*$O$11)+(D15*$O$12)+(E15*$O$13)+(F15*$O$14)+$O$8 -> 8459.0924 | I15: =G15-H15 -> 3075.7802 | J15: =I15^2 -> 9460424.1 | K15: =ABS(I15) -> 3075.7802 | L15: =K15/G15*100 -> 26.665056
A16: 51 | B16: 1 | C16: 42.9 | D16: 2 | E16: 1 | F16: 1 | G16: 47462.894 | H16: =(A16*$O$9)+(B16*$O$10)+(C16*$O$11)+(D16*$O$12)+(E16*$O$13)+(F16*$O$14)+$O$8 -> 39518.76 | I16: =G16-H16 -> 7944.1343 | J16: =I16^2 -> 63109270 | K16: =ABS(I16) -> 7944.1343 | L16: =K16/G16*100 -> 16.737568
A17: 30 | B17: 0 | C17: 28.405 | D17: 1 | E17: 0 | F17: 3 | G17: 4527.183 | H17: =(A17*$O$9)+(B17*$O$10)+(C17*$O$11)+(D17*$O$12)+(E17*$O$13)+(F17*$O$14)+$O$8 -> 4991.6828 | I17: =G17-H17 -> -464.49982 | J17: =I17^2 -> 215760.09 | K17: =ABS(I17) -> 464.49982 | L17: =K17/G17*100 -> 10.26024
A18: 44 | B18: 1 | C18: 30.2 | D18: 2 | E18: 1 | F18: 2 | G18: 38998.546 | H18: =(A18*$O$9)+(B18*$O$10)+(C18*$O$11)+(D18*$O$12)+(E18*$O$13)+(F18*$O$14)+$O$8 -> 33466.592 | I18: =G18-H18 -> 5531.9536 | J18: =I18^2 -> 30602511 | K18: =ABS(I18) -> 5531.9536 | L18: =K18/G18*100 -> 14.185025
A19: 34 | B19: 1 | C19: 27.835 | D19: 1 | E19: 1 | F19: 3 | G19: 20009.634 | H19: =(A19*$O$9)+(B19*$O$10)+(C19*$O$11)+(D19*$O$12)+(E19*$O$13)+(F19*$O$14)+$O$8 -> 29507.365 | I19: =G19-H19 -> -9497.7315 | J19: =I19^2 -> 90206903 | K19: =ABS(I19) -> 9497.7315 | L19: =K19/G19*100 -> 47.465794
A20: 31 | B20: 1 | C20: 39.49 | D20: 1 | E20: 0 | F20: 1 | G20: 3875.7341 | H20: =(A20*$O$9)+(B20*$O$10)+(C20*$O$11)+(D20*$O$12)+(E20*$O$13)+(F20*$O$14)+$O$8 -> 8748.9449 | I20: =G20-H20 -> -4873.2108 | J20: =I20^2 -> 23748184 | K20: =ABS(I20) -> 4873.2108 | L20: =K20/G20*100 -> 125.73646
A21: 54 | B21: 1 | C21: 30.8 | D21: 1 | E21: 1 | F21: 1 | G21: 41999.52 | H21: =(A21*$O$9)+(B21*$O$10)+(C21*$O$11)+(D21*$O$12)+(E21*$O$13)+(F21*$O$14)+$O$8 -> 35981.615 | I21: =G21-H21 -> 6017.905 | J21: =I21^2 -> 36215181 | K21: =ABS(I21) -> 6017.905 | L21: =K21/G21*100 -> 14.328509
A22: 24 | B22: 1 | C22: 26.79 | D22: 1 | E22: 0 | F22: 3 | G22: 12609.887 | H22: =(A22*$O$9)+(B22*$O$10)+(C22*$O$11)+(D22*$O$12)+(E22*$O$13)+(F22*$O$14)+$O$8 -> 2542.2051 | I22: =G22-H22 -> 10067.682 | J22: =I22^2 -> 1.0135822e+08 | K22: =ABS(I22) -> 10067.682 | L22: =K22/G22*100 -> 79.839588
A23: 43 | B23: 1 | C23: 34.96 | D23: 1 | E23: 1 | F23: 0 | G23: 41034.221 | H23: =(A23*$O$9)+(B23*$O$10)+(C23*$O$11)+(D23*$O$12)+(E23*$O$13)+(F23*$O$14)+$O$8 -> 34602.337 | I23: =G23-H23 -> 6431.8848 | J23: =I23^2 -> 41369142 | K23: =ABS(I23) -> 6431.8848 | L23: =K23/G23*100 -> 15.674441
A24: 48 | B24: 1 | C24: 36.67 | D24: 1 | E24: 0 | F24: 3 | G24: 28468.919 | H24: =(A24*$O$9)+(B24*$O$10)+(C24*$O$11)+(D24*$O$12)+(E24*$O$13)+(F24*$O$14)+$O$8 -> 11967.647 | I24: =G24-H24 -> 16501.272 | J24: =I24^2 -> 2.7229198e+08 | K24: =ABS(I24) -> 16501.272 | L24: =K24/G24*100 -> 57.962412
A25: 19 | B25: 0 | C25: 39.615 | D25: 1 | E25: 0 | F25: 3 | G25: 2730.1078 | H25: =(A25*$O$9)+(B25*$O$10)+(C25*$O$11)+(D25*$O$12)+(E25*$O$13)+(F25*$O$14)+$O$8 -> 5718.6003 | I25: =G25-H25 -> -2988.4925 | J25: =I25^2 -> 8931087.3 | K25: =ABS(I25) -> 2988.4925 | L25: =K25/G25*100 -> 109.46426
A26: 29 | B26: 0 | C26: 25.9 | D26: 0 | E26: 0 | F26: 2 | G26: 3353.284 | H26: =(A26*$O$9)+(B26*$O$10)+(C26*$O$11)+(D26*$O$12)+(E26*$O$13)+(F26*$O$14)+$O$8 -> 3643.1406 | I26: =G26-H26 -> -289.85657 | J26: =I26^2 -> 84016.832 | K26: =ABS(I26) -> 289.85657 | L26: =K26/G26*100 -> 8.6439613
... A402: 61 | B402: 0 | C402: 29.07 | D402: 0 | E402: 1 | F402: 3 | G402: 29141.36 | H402: =(A402*$O$9)+(B402*$O$10)+(C402*$O$11)+(D402*$O$12)+(E402*$O$13)+(F402*$O$14)+$O$8 -> 36870.895 | I402: =G402-H402 -> -7729.5344 | J402: =I402^2 -> 59745702 | K402: =ABS(I402) -> 7729.5344 | L402: =K402/G402*100 -> 26.524275
